<?xml version="1.0" ?>
<!-- =================================================================================== -->
<!-- |    This document was autogenerated by xacro from /home/lpy/waao_hunter/src/hunter_bipedal_control/legged_examples/legged_hunter/legged_hunter_description/urdf/robot.xacro | -->
<!-- |    EDITING THIS FILE BY HAND IS NOT RECOMMENDED                                 | -->
<!-- =================================================================================== -->
<robot name="hunter">
  <!-- <link name="world" />
  <joint name ="weld" type="fixed">
    <parent link="world"/>
    <child link="base_link"/>
    <origin xyz="0 0 0.3"/>
  </joint> -->
  <gazebo>
    <plugin filename="libhunter_bipedal_hw_sim.so" name="gazebo_ros_control">
      <robotNamespace>/</robotNamespace>
      <robotParam>legged_robot_description</robotParam>
      <robotSimType>legged_gazebo/LeggedHWSim</robotSimType>
    </plugin>
  </gazebo>
  <gazebo>
    <plugin filename="libgazebo_ros_p3d.so" name="p3d_base_controller">
      <alwaysOn>true</alwaysOn>
      <updateRate>500.0</updateRate>
      <bodyName>base_link</bodyName>
      <topicName>ground_truth/state</topicName>
      <gaussianNoise>0</gaussianNoise>
      <frameName>world</frameName>
      <xyzOffsets>0 0 0</xyzOffsets>
      <rpyOffsets>0 0 0</rpyOffsets>
    </plugin>
  </gazebo>
  <link name="base_link">
    <inertial>
      <origin rpy="0 0 0" xyz="-0.02983954 0.00086547 0.14856051"/>
      <mass value="18.945426"/>
      <inertia ixx="0.49280384" ixy="-0.00038292" ixz="-0.04951313" iyy="0.42814074" iyz="-0.00020145" izz="0.15555181"/>
    </inertial>
    <visual>
      <origin rpy="0 0 0" xyz="0 0 0"/>
      <geometry>
        <mesh filename="package://legged_hunter_description/meshes/base_link.STL"/>
      </geometry>
      <material name="">
        <color rgba="0.75294 0.75294 0.75294 1"/>
      </material>
    </visual>
    <collision>
      <origin rpy="0 0 0" xyz="-0.01 0 0.206"/>
      <geometry>
        <box size="0.184 0.15 0.2"/>
        <!--宽 长 高!-->
      </geometry>
    </collision>
  </link>
  <!-- Imu is fixed to the base link -->
  <joint name="imu_joint" type="fixed">
    <origin rpy="0. 0. 0." xyz="0. 0. 0"/>
    <parent link="base_link"/>
    <child link="imu_link"/>
  </joint>
  <!-- Imu link -->
  <link name="imu_link">
    <inertial>
      <mass value="0.01"/>
      <origin rpy="0 0 0" xyz="0 0 0"/>
      <inertia ixx="0.000001" ixy="0" ixz="0" iyy="0.000001" iyz="0" izz="0.000001"/>
    </inertial>
    <visual>
      <origin rpy="0 0 0" xyz="0 0 0"/>
      <geometry>
        <box size="0.015 0.015 0.004"/>
      </geometry>
    </visual>
    <material name="orange">
      <color rgba="255 108 10 255"/>
    </material>
  </link>
  <gazebo reference="imu_joint">
    <disableFixedJointLumping>true</disableFixedJointLumping>
  </gazebo>
  <!-- ************************************************************ -->
  <!-- ************************ Left Leg ************************** -->
  <!-- ************************************************************ -->
  <!-- ************* part 1 *************** -->
  <joint name="leg_l1_joint" type="revolute">
    <origin rpy="0 0 0" xyz="-0.08 0.105 -0.0675"/>
    <parent link="base_link"/>
    <child link="leg_l1_link"/>
    <axis xyz="1 0 0"/>
    <dynamics damping="0.00" friction="0.2"/>
    <limit effort="300" lower="-0.5" upper="0.5" velocity="18"/>
  </joint>
  <link name="leg_l1_link">
    <inertial>
      <origin rpy="0 0 0" xyz="0.10000784 -0.00009881 0.01657766"/>
      <mass value="1.54"/>
      <inertia ixx="0.00139323" ixy="-0.00000019" ixz="-0.00000048" iyy="0.00140374" iyz="0.00000650" izz="0.00173658"/>
    </inertial>
    <visual>
      <origin rpy="0 0 0" xyz="0 0 0"/>
      <geometry>
        <mesh filename="package://legged_hunter_description/meshes/leg_l1_link.STL"/>
      </geometry>
      <material name="">
        <color rgba="0.75294 0.75294 0.75294 1"/>
      </material>
    </visual>
    <collision>
      <origin rpy="1.57 0 1.57" xyz="-0.019 -0.001 0"/>
      <geometry>
        <box size="0.006 0.007 0.0155"/>
      </geometry>
    </collision>
  </link>
  <!-- ************* part 2 *************** -->
  <joint name="leg_l2_joint" type="revolute">
    <origin rpy="0 0 0" xyz="0.080001 0 0"/>
    <parent link="leg_l1_link"/>
    <child link="leg_l2_link"/>
    <axis xyz="0 0 1"/>
    <dynamics damping="0.00" friction="0.2"/>
    <limit effort="300" lower="-0.6" upper="0.6" velocity="18"/>
  </joint>
  <link name="leg_l2_link">
    <inertial>
      <origin rpy="0 0 0" xyz="0.00007811 0.00423442 -0.08994449"/>
      <mass value="2.7"/>
      <inertia ixx="0.00335768" ixy="-0.00001160" ixz="0.00000108" iyy="0.00323199" iyz="-0.00000465" izz="0.00335678"/>
    </inertial>
    <visual>
      <origin rpy="0 0 0" xyz="0 0 0"/>
      <geometry>
        <mesh filename="package://legged_hunter_description/meshes/leg_l2_link.STL"/>
      </geometry>
      <material name="">
        <color rgba="0.75294 0.75294 0.75294 1"/>
      </material>
    </visual>
    <collision>
      <origin rpy="1.57 0 0" xyz="0 0.0046 -0.057"/>
      <geometry>
        <cylinder length="0.00146" radius="0.0025"/>
      </geometry>
    </collision>
  </link>
  <!-- ************* part 3 *************** -->
  <joint name="leg_l3_joint" type="revolute">
    <origin rpy="0 0 0" xyz="0 0 -0.090001"/>
    <parent link="leg_l2_link"/>
    <child link="leg_l3_link"/>
    <axis xyz="0 1 0"/>
    <dynamics damping="0.00" friction="0.2"/>
    <limit effort="300" lower="-1.5" upper="0.5" velocity="17"/>
  </joint>
  <link name="leg_l3_link">
    <inertial>
      <origin rpy="0 0 0" xyz="0.00039619 0.04119274 -0.15289538"/>
      <mass value="4.8"/>
      <inertia ixx="0.04694541" ixy="0.00009678" ixz="0.00068599" iyy="0.04241315" iyz="-0.00410792" izz="0.01237341"/>
    </inertial>
    <visual>
      <origin rpy="0 0 0" xyz="0 0 0"/>
      <geometry>
        <mesh filename="package://legged_hunter_description/meshes/leg_l3_link.STL"/>
      </geometry>
      <material name="">
        <color rgba="0.75294 0.75294 0.75294 1"/>
      </material>
    </visual>
    <collision>
      <origin rpy="1.57 0 0" xyz="0.015 0.02 -0.1"/>
      <geometry>
        <box size="0.006 0.025 0.005"/>
      </geometry>
    </collision>
  </link>
  <!-- ************* part 4 *************** -->
  <joint name="leg_l4_joint" type="revolute">
    <origin rpy="0 0 0" xyz="0 0 -0.38"/>
    <parent link="leg_l3_link"/>
    <child link="leg_l4_link"/>
    <axis xyz="0 1 0"/>
    <dynamics damping="0.00" friction="0.2"/>
    <limit effort="300" lower="0.1" upper="2.5" velocity="17"/>
  </joint>
  <link name="leg_l4_link">
    <inertial>
      <origin rpy="0 0 0" xyz="0.00066117 0.00034461 -0.14038088"/>
      <mass value="2.9"/>
      <inertia ixx="0.04319157" ixy="0.00000750" ixz="-0.00073877" iyy="0.04385624" iyz="0.00049349" izz="0.00190256"/>
    </inertial>
    <visual>
      <origin rpy="0 0 0" xyz="0 0 0"/>
      <geometry>
        <mesh filename="package://legged_hunter_description/meshes/leg_l4_link.STL"/>
      </geometry>
      <material name="">
        <color rgba="0.75294 0.75294 0.75294 1"/>
      </material>
    </visual>
    <collision>
      <origin rpy="1.57 0 0" xyz="0 0 -0.18"/>
      <geometry>
        <box size="0.0041 0.025 0.003"/>
      </geometry>
    </collision>
    <collision>
      <origin rpy="1.57 0 0" xyz="-0.011 0.012 -0.079"/>
      <geometry>
        <cylinder length="0.007" radius="0.0034"/>
      </geometry>
    </collision>
  </link>
  <!-- ************* part 5 *************** -->
  <joint name="leg_l5_joint" type="revolute">
    <origin rpy="0 0 0" xyz="0 0 -0.38"/>
    <parent link="leg_l4_link"/>
    <child link="leg_l5_link"/>
    <axis xyz="0 1 0"/>
    <dynamics damping="0.02" friction="0.02"/>
    <limit effort="300" lower="-1.5" upper="1.5" velocity="15.49"/>
  </joint>
  <link name="leg_l5_link">
    <inertial>
      <origin rpy="0 0 0" xyz="-0.00518023 0.00000000 -0.00246757"/>
      <mass value="0.125"/>
      <inertia ixx="0.00000749" ixy="0.00000000" ixz="-0.00000017" iyy="0.00006652" iyz="0.00000000" izz="0.00006206"/>
    </inertial>
    <visual>
      <origin rpy="0 0 0" xyz="0 0 0"/>
      <geometry>
        <mesh filename="package://legged_hunter_description/meshes/leg_l5_link.STL"/>
      </geometry>
      <material name="">
        <color rgba="0.75294 0.75294 0.75294 1"/>
      </material>
    </visual>
    <!--collision>
      <origin xyz="0.0 0 -0.0" rpy="1.57 0 0" />
      <geometry>
        <cylinder length="0.007" radius="0.001"/>
      </geometry>
    </collision-->
  </link>
  <!-- ************* part 6 *************** -->
  <joint name="leg_l6_joint" type="revolute">
    <origin rpy="0 0 0" xyz="0 0 0"/>
    <parent link="leg_l5_link"/>
    <child link="leg_l6_link"/>
    <axis xyz="1 0 0"/>
    <dynamics damping="0.02" friction="0.02"/>
    <limit effort="300" lower="-1.5" upper="1.5" velocity="15.49"/>
  </joint>
  <link name="leg_l6_link">
    <inertial>
      <origin rpy="0 0 0" xyz="0.01218965 0.00000000 -0.01997971"/>
      <mass value="0.56"/>
      <inertia ixx="0.00030271" ixy="0.00000000" ixz="0.00012599" iyy="0.00193585" iyz="0.00000000" izz="0.00200345"/>
    </inertial>
    <visual>
      <origin rpy="0 0 0" xyz="0 0 0"/>
      <geometry>
        <mesh filename="package://legged_hunter_description/meshes/leg_l6_link.STL"/>
      </geometry>
      <material name="">
        <color rgba="1 1 1 1"/>
      </material>
    </visual>
    <collision>
      <origin rpy="0 0 0" xyz="0.03 0 -0.033"/>
      <geometry>
        <box size="0.230 0.08 0.015"/>
      </geometry>
    </collision>
  </link>
  <!-- ************* fixed joint & link *************** -->
  <joint name="leg_l6_fixed_1" type="fixed">
    <origin rpy="0 0 0" xyz="0.13 -0.04 -0.038"/>
    <parent link="leg_l6_link"/>
    <child link="leg_l_f1_link"/>
  </joint>
  <link name="leg_l_f1_link">
    <inertial>
      <mass value="0.01"/>
      <inertia ixx="0.000001" ixy="0" ixz="0" iyy="0.000001" iyz="0" izz="0.000001"/>
    </inertial>
    <visual>
      <origin rpy="0 0 0" xyz="0 0 0"/>
      <geometry>
        <sphere radius="0.001"/>
      </geometry>
    </visual>
    <collision>
      <origin rpy="0 0 0" xyz="0 0 0"/>
      <geometry>
        <sphere radius="0.001"/>
      </geometry>
    </collision>
  </link>
  <joint name="leg_l6_fixed_2" type="fixed">
    <origin rpy="0 0 0" xyz="-0.09 -0.04 -0.038"/>
    <parent link="leg_l6_link"/>
    <child link="leg_l_f2_link"/>
  </joint>
  <link name="leg_l_f2_link">
    <inertial>
      <mass value="0.01"/>
      <inertia ixx="0.000001" ixy="0" ixz="0" iyy="0.000001" iyz="0" izz="0.000001"/>
    </inertial>
    <visual>
      <origin rpy="0 0 0" xyz="0 0 0"/>
      <geometry>
        <sphere radius="0.001"/>
      </geometry>
    </visual>
    <collision>
      <origin rpy="0 0 0" xyz="-0 0 0"/>
      <geometry>
        <sphere radius="0.001"/>
      </geometry>
    </collision>
  </link>
  <joint name="leg_l6_fixed_3" type="fixed">
    <origin rpy="0 0 0" xyz="0.13 0.04 -0.038"/>
    <parent link="leg_l6_link"/>
    <child link="leg_l_f3_link"/>
  </joint>
  <link name="leg_l_f3_link">
    <inertial>
      <mass value="0.01"/>
      <inertia ixx="0.000001" ixy="0" ixz="0" iyy="0.000001" iyz="0" izz="0.000001"/>
    </inertial>
    <visual>
      <origin rpy="0 0 0" xyz="0 0 0"/>
      <geometry>
        <sphere radius="0.001"/>
      </geometry>
    </visual>
    <collision>
      <origin rpy="0 0 0" xyz="0 0 0"/>
      <geometry>
        <sphere radius="0.001"/>
      </geometry>
    </collision>
  </link>
  <joint name="leg_l6_fixed_4" type="fixed">
    <origin rpy="0 0 0" xyz="-0.09 0.04 -0.038"/>
    <parent link="leg_l6_link"/>
    <child link="leg_l_f4_link"/>
  </joint>
  <link name="leg_l_f4_link">
    <inertial>
      <mass value="0.01"/>
      <inertia ixx="0.000001" ixy="0" ixz="0" iyy="0.000001" iyz="0" izz="0.000001"/>
    </inertial>
    <visual>
      <origin rpy="0 0 0" xyz="0 0 0"/>
      <geometry>
        <sphere radius="0.001"/>
      </geometry>
    </visual>
    <collision>
      <origin rpy="0 0 0" xyz="-0 0 0"/>
      <geometry>
        <sphere radius="0.001"/>
      </geometry>
    </collision>
  </link>
  <!-- ************* gazebo reference *************** -->
  <gazebo reference="leg_l1_link">
    <mu1>0.6</mu1>
    <mu2>0.6</mu2>
    <self_collide>1</self_collide>
  </gazebo>
  <gazebo reference="leg_l2_link">
    <mu1>0.6</mu1>
    <mu2>0.6</mu2>
    <self_collide>1</self_collide>
  </gazebo>
  <gazebo reference="leg_l3_link">
    <mu1>0.6</mu1>
    <mu2>0.6</mu2>
    <self_collide>1</self_collide>
  </gazebo>
  <gazebo reference="leg_l4_link">
    <mu1>0.6</mu1>
    <mu2>0.6</mu2>
    <self_collide>1</self_collide>
  </gazebo>
  <gazebo reference="leg_l5_link">
    <mu1>0.6</mu1>
    <mu2>0.6</mu2>
  </gazebo>
  <gazebo reference="leg_l6_link">
    <mu1>1.5</mu1>
    <mu2>1.5</mu2>
    <self_collide>1</self_collide>
    <kp value="1000000.0"/>
    <kd value="100.0"/>
    <maxVel>1.0</maxVel>
    <minDepth>0.00</minDepth>
  </gazebo>
  <gazebo reference="leg_l_f1_link">
    <mu1>1.5</mu1>
    <mu2>1.5</mu2>
    <self_collide>1</self_collide>
    <kp value="1000000.0"/>
    <kd value="100.0"/>
    <maxVel>1.0</maxVel>
    <minDepth>0.00</minDepth>
  </gazebo>
  <gazebo reference="leg_l_f2_link">
    <mu1>1.5</mu1>
    <mu2>1.5</mu2>
    <self_collide>1</self_collide>
    <kp value="1000000.0"/>
    <kd value="100.0"/>
    <maxVel>1.0</maxVel>
    <minDepth>0.00</minDepth>
  </gazebo>
  <gazebo reference="leg_l_f3_link">
    <mu1>1.5</mu1>
    <mu2>1.5</mu2>
    <self_collide>1</self_collide>
    <kp value="1000000.0"/>
    <kd value="100.0"/>
    <maxVel>1.0</maxVel>
    <minDepth>0.00</minDepth>
  </gazebo>
  <gazebo reference="leg_l_f4_link">
    <mu1>1.5</mu1>
    <mu2>1.5</mu2>
    <self_collide>1</self_collide>
    <kp value="1000000.0"/>
    <kd value="100.0"/>
    <maxVel>1.0</maxVel>
    <minDepth>0.00</minDepth>
  </gazebo>
  <!-- ************* transmission *************** -->
  <transmission name="leg_l1_tran">
    <type>transmission_interface/SimpleTransmission</type>
    <joint name="leg_l1_joint">
      <hardwareInterface>hardware_interface/EffortJointInterface</hardwareInterface>
    </joint>
    <actuator name="leg_l1_motor">
      <hardwareInterface>hardware_interface/EffortJointInterface</hardwareInterface>
      <mechanicalReduction>1</mechanicalReduction>
      <maxVelocity>2.87</maxVelocity>
      <!-- 85rpm -->
      <maxEffort>182</maxEffort>
      <!-- 36Nm -->
    </actuator>
  </transmission>
  <transmission name="leg_l2_tran">
    <type>transmission_interface/SimpleTransmission</type>
    <joint name="leg_l2_joint">
      <hardwareInterface>hardware_interface/EffortJointInterface</hardwareInterface>
    </joint>
    <actuator name="leg_l2_motor">
      <hardwareInterface>hardware_interface/EffortJointInterface</hardwareInterface>
      <mechanicalReduction>1</mechanicalReduction>
      <maxVelocity>2.87</maxVelocity>
      <!-- 160rpm -->
      <maxEffort>182</maxEffort>
      <!-- 94Nm -->
    </actuator>
  </transmission>
  <transmission name="leg_l3_tran">
    <type>transmission_interface/SimpleTransmission</type>
    <joint name="leg_l3_joint">
      <hardwareInterface>hardware_interface/EffortJointInterface</hardwareInterface>
    </joint>
    <actuator name="leg_l3_motor">
      <hardwareInterface>hardware_interface/EffortJointInterface</hardwareInterface>
      <mechanicalReduction>1</mechanicalReduction>
      <maxVelocity>2.6545</maxVelocity>
      <!-- 160rpm -->
      <maxEffort>278</maxEffort>
      <!-- 94Nm -->
    </actuator>
  </transmission>
  <transmission name="leg_l4_tran">
    <type>transmission_interface/SimpleTransmission</type>
    <joint name="leg_l4_joint">
      <hardwareInterface>hardware_interface/EffortJointInterface</hardwareInterface>
    </joint>
    <actuator name="leg_l4_motor">
      <hardwareInterface>hardware_interface/EffortJointInterface</hardwareInterface>
      <mechanicalReduction>1</mechanicalReduction>
      <maxVelocity>2.6545</maxVelocity>
      <!-- 85rpm -->
      <maxEffort>278</maxEffort>
      <!-- 36Nm -->
    </actuator>
  </transmission>
  <transmission name="leg_l5_tran">
    <type>transmission_interface/SimpleTransmission</type>
    <joint name="leg_l5_joint">
      <hardwareInterface>hardware_interface/EffortJointInterface</hardwareInterface>
    </joint>
    <actuator name="leg_l5_motor">
      <hardwareInterface>hardware_interface/EffortJointInterface</hardwareInterface>
      <mechanicalReduction>1</mechanicalReduction>
    </actuator>
  </transmission>
  <transmission name="leg_l6_tran">
    <type>transmission_interface/SimpleTransmission</type>
    <joint name="leg_l6_joint">
      <hardwareInterface>hardware_interface/EffortJointInterface</hardwareInterface>
    </joint>
    <actuator name="leg_l6_motor">
      <hardwareInterface>hardware_interface/EffortJointInterface</hardwareInterface>
      <mechanicalReduction>1</mechanicalReduction>
    </actuator>
  </transmission>
  <!-- ************************************************************ -->
  <!-- ************************ Right Leg ************************** -->
  <!-- ************************************************************ -->
  <!-- ************* part 1 *************** -->
  <joint name="leg_r1_joint" type="revolute">
    <origin rpy="0 0 0" xyz="-0.08 -0.105 -0.0675"/>
    <parent link="base_link"/>
    <child link="leg_r1_link"/>
    <axis xyz="1 0 0"/>
    <dynamics damping="0.00" friction="0.2"/>
    <limit effort="300" lower="-0.5" upper="0.5" velocity="18"/>
  </joint>
  <link name="leg_r1_link">
    <inertial>
      <origin rpy="0 0 0" xyz="0.07867925 -0.00007201 0.00877160"/>
      <mass value="1.54"/>
      <inertia ixx="0.00139323" ixy="-0.00000019" ixz="0.00000048" iyy="0.00140374" iyz="-0.00000650" izz="0.00173658"/>
    </inertial>
    <visual>
      <origin rpy="0 0 0" xyz="0 0 0"/>
      <geometry>
        <mesh filename="package://legged_hunter_description/meshes/leg_r1_link.STL"/>
      </geometry>
      <material name="">
        <color rgba="0.75294 0.75294 0.75294 1"/>
      </material>
    </visual>
    <collision>
      <origin rpy="1.57 0 1.57" xyz="-0.019 -0.001 0"/>
      <geometry>
        <box size="0.006 0.007 0.0155"/>
      </geometry>
    </collision>
  </link>
  <!-- ************* part 2 *************** -->
  <joint name="leg_r2_joint" type="revolute">
    <origin rpy="0 0 0" xyz="0.080001 0 0"/>
    <parent link="leg_r1_link"/>
    <child link="leg_r2_link"/>
    <axis xyz="0 0 1"/>
    <dynamics damping="0.00" friction="0.2"/>
    <limit effort="300" lower="-0.6" upper="0.6" velocity="18"/>
  </joint>
  <link name="leg_r2_link">
    <inertial>
      <origin rpy="0 0 0" xyz="-0.00007811 -0.00423442 -0.15499595"/>
      <mass value="2.7"/>
      <inertia ixx="0.00335768" ixy="-0.00001160" ixz="-0.00000108" iyy="0.00323199" iyz="0.00000465" izz="0.00335678"/>
    </inertial>
    <visual>
      <origin rpy="0 0 0" xyz="0 0 0"/>
      <geometry>
        <mesh filename="package://legged_hunter_description/meshes/leg_r2_link.STL"/>
      </geometry>
      <material name="">
        <color rgba="0.75294 0.75294 0.75294 1"/>
      </material>
    </visual>
    <collision>
      <origin rpy="1.57 0 0" xyz="0 -0.0033 -0.057"/>
      <geometry>
        <cylinder length="0.00146" radius="0.0015"/>
      </geometry>
    </collision>
  </link>
  <!-- ************* part 3 *************** -->
  <joint name="leg_r3_joint" type="revolute">
    <origin rpy="0 0 0" xyz="0 0 -0.090001"/>
    <parent link="leg_r2_link"/>
    <child link="leg_r3_link"/>
    <axis xyz="0 1 0"/>
    <dynamics damping="0.00" friction="0.2"/>
    <limit effort="300" lower="-1.5" upper="0.5" velocity="17"/>
  </joint>
  <link name="leg_r3_link">
    <inertial>
      <origin rpy="0 0 0" xyz="0.00044061 -0.04113251 -0.15499595"/>
      <mass value="4.8"/>
      <inertia ixx="0.04859117" ixy="-0.00008785" ixz="0.00069103" iyy="0.04399962" iyz="0.00445708" izz="0.01238287"/>
    </inertial>
    <visual>
      <origin rpy="0 0 0" xyz="0 0 0"/>
      <geometry>
        <mesh filename="package://legged_hunter_description/meshes/leg_r3_link.STL"/>
      </geometry>
      <material name="">
        <color rgba="0.75294 0.75294 0.75294 1"/>
      </material>
    </visual>
    <collision>
      <origin rpy="1.57 0 0" xyz="0.015 -0.02 -0.1"/>
      <geometry>
        <box size="0.006 0.025 0.005"/>
      </geometry>
    </collision>
  </link>
  <!-- ************* part 4 *************** -->
  <joint name="leg_r4_joint" type="revolute">
    <origin rpy="0 0 0" xyz="0 0 -0.38"/>
    <parent link="leg_r3_link"/>
    <child link="leg_r4_link"/>
    <axis xyz="0 1 0"/>
    <dynamics damping="0.00" friction="0.2"/>
    <limit effort="300" lower="0.1" upper="2.5" velocity="17"/>
  </joint>
  <link name="leg_r4_link">
    <inertial>
      <origin rpy="0 0 0" xyz="0.00066117 -0.00034461 -0.14038088"/>
      <mass value="2.9"/>
      <inertia ixx="0.04319157" ixy="-0.00000750" ixz="-0.00073877" iyy="0.04385624" iyz="-0.00049349" izz="0.00190256"/>
    </inertial>
    <visual>
      <origin rpy="0 0 0" xyz="0 0 0"/>
      <geometry>
        <mesh filename="package://legged_hunter_description/meshes/leg_r4_link.STL"/>
      </geometry>
      <material name="">
        <color rgba="0.75294 0.75294 0.75294 1"/>
      </material>
    </visual>
    <collision>
      <origin rpy="1.57 0 0" xyz="0 0 -0.18"/>
      <geometry>
        <box size="0.0041 0.025 0.003"/>
      </geometry>
    </collision>
    <collision>
      <origin rpy="1.57 0 0" xyz="-0.011 -0.012 -0.079"/>
      <geometry>
        <cylinder length="0.07" radius="0.034"/>
      </geometry>
    </collision>
  </link>
  <!-- ************* part 5 *************** -->
  <joint name="leg_r5_joint" type="revolute">
    <origin rpy="0 0 0" xyz="0 0 -0.38"/>
    <parent link="leg_r4_link"/>
    <child link="leg_r5_link"/>
    <axis xyz="0 1 0"/>
    <dynamics damping="0.02" friction="0.02"/>
    <limit effort="300" lower="-1.5" upper="1.5" velocity="15.49"/>
  </joint>
  <link name="leg_r5_link">
    <inertial>
      <origin rpy="0 0 0" xyz="-0.00518023 0.000000 -0.00246757"/>
      <mass value="0.125"/>
      <inertia ixx="0.00000749" ixy="0.00000000" ixz="-0.00000017" iyy="0.00006652" iyz="0.00000000" izz="0.00006206"/>
    </inertial>
    <visual>
      <origin rpy="0 0 0" xyz="0 0 0"/>
      <geometry>
        <mesh filename="package://legged_hunter_description/meshes/leg_r5_link.STL"/>
      </geometry>
      <material name="">
        <color rgba="0.75294 0.75294 0.75294 1"/>
      </material>
    </visual>
    <!--collision>
      <origin xyz="0.0 0 -0.0" rpy="1.57 0 0" />
      <geometry>
        <cylinder length="0.007" radius="0.001"/>
      </geometry>
    </collision-->
  </link>
  <!-- ************* part 6 *************** -->
  <joint name="leg_r6_joint" type="revolute">
    <origin rpy="0 0 0" xyz="0 0 0"/>
    <parent link="leg_r5_link"/>
    <child link="leg_r6_link"/>
    <axis xyz="1 0 0"/>
    <dynamics damping="0.02" friction="0.02"/>
    <limit effort="300" lower="-1.5" upper="1.5" velocity="15.49"/>
  </joint>
  <link name="leg_r6_link">
    <inertial>
      <origin rpy="0 0 0" xyz="0.01218965 0.00000000 -0.01997971"/>
      <mass value="0.56"/>
      <inertia ixx="0.00030271" ixy="0.00000000" ixz="0.00012599" iyy="0.00193585" iyz="0.00000000" izz="0.00200345"/>
    </inertial>
    <visual>
      <origin rpy="0 0 0" xyz="0 0 0"/>
      <geometry>
        <mesh filename="package://legged_hunter_description/meshes/leg_r6_link.STL"/>
      </geometry>
      <material name="">
        <color rgba="1 1 1 1"/>
      </material>
    </visual>
    <collision>
      <origin rpy="0 0 0" xyz="0.03 0 -0.033"/>
      <geometry>
        <box size="0.230 0.08 0.015"/>
      </geometry>
    </collision>
  </link>
  <!-- ************* fixed joint *************** -->
  <joint name="leg_r6_fixed_1" type="fixed">
    <origin rpy="0 0 0" xyz="0.13 -0.04 -0.038"/>
    <parent link="leg_r6_link"/>
    <child link="leg_r_f1_link"/>
  </joint>
  <link name="leg_r_f1_link">
    <inertial>
      <mass value="0.01"/>
      <inertia ixx="0.000001" ixy="0" ixz="0" iyy="0.000001" iyz="0" izz="0.000001"/>
    </inertial>
    <visual>
      <origin rpy="0 0 0" xyz="0 0 0"/>
      <geometry>
        <sphere radius="0.001"/>
      </geometry>
    </visual>
    <collision>
      <origin rpy="0 0 0" xyz="0 0 0"/>
      <geometry>
        <sphere radius="0.001"/>
      </geometry>
    </collision>
  </link>
  <joint name="leg_r6_fixed_2" type="fixed">
    <origin rpy="0 0 0" xyz="-0.090 -0.04 -0.038"/>
    <parent link="leg_r6_link"/>
    <child link="leg_r_f2_link"/>
  </joint>
  <link name="leg_r_f2_link">
    <inertial>
      <mass value="0.01"/>
      <inertia ixx="0.000001" ixy="0" ixz="0" iyy="0.000001" iyz="0" izz="0.000001"/>
    </inertial>
    <visual>
      <origin rpy="0 0 0" xyz="0 0 0"/>
      <geometry>
        <sphere radius="0.001"/>
      </geometry>
    </visual>
    <collision>
      <origin rpy="0 0 0" xyz="0 0 0"/>
      <geometry>
        <sphere radius="0.001"/>
      </geometry>
    </collision>
  </link>
  <joint name="leg_r6_fixed_3" type="fixed">
    <origin rpy="0 0 0" xyz="0.13 0.04 -0.038"/>
    <parent link="leg_r6_link"/>
    <child link="leg_r_f3_link"/>
  </joint>
  <link name="leg_r_f3_link">
    <inertial>
      <mass value="0.01"/>
      <inertia ixx="0.000001" ixy="0" ixz="0" iyy="0.000001" iyz="0" izz="0.000001"/>
    </inertial>
    <visual>
      <origin rpy="0 0 0" xyz="0 0 0"/>
      <geometry>
        <sphere radius="0.001"/>
      </geometry>
    </visual>
    <collision>
      <origin rpy="0 0 0" xyz="0 0 0"/>
      <geometry>
        <sphere radius="0.001"/>
      </geometry>
    </collision>
  </link>
  <joint name="leg_r6_fixed_4" type="fixed">
    <origin rpy="0 0 0" xyz="-0.090 0.04 -0.038"/>
    <parent link="leg_r6_link"/>
    <child link="leg_r_f4_link"/>
  </joint>
  <link name="leg_r_f4_link">
    <inertial>
      <mass value="0.01"/>
      <inertia ixx="0.000001" ixy="0" ixz="0" iyy="0.000001" iyz="0" izz="0.000001"/>
    </inertial>
    <visual>
      <origin rpy="0 0 0" xyz="0 0 0"/>
      <geometry>
        <sphere radius="0.001"/>
      </geometry>
    </visual>
    <collision>
      <origin rpy="0 0 0" xyz="0 0 0"/>
      <geometry>
        <sphere radius="0.001"/>
      </geometry>
    </collision>
  </link>
  <!-- ************* gazebo reference *************** -->
  <gazebo reference="leg_r1_link">
    <mu1>0.6</mu1>
    <mu2>0.6</mu2>
    <self_collide>1</self_collide>
  </gazebo>
  <gazebo reference="leg_r2_link">
    <mu1>0.6</mu1>
    <mu2>0.6</mu2>
    <self_collide>1</self_collide>
  </gazebo>
  <gazebo reference="leg_r3_link">
    <mu1>0.6</mu1>
    <mu2>0.6</mu2>
    <self_collide>1</self_collide>
  </gazebo>
  <gazebo reference="leg_r4_link">
    <mu1>0.6</mu1>
    <mu2>0.6</mu2>
    <self_collide>1</self_collide>
  </gazebo>
  <gazebo reference="leg_r5_link">
    <mu1>0.6</mu1>
    <mu2>0.6</mu2>
  </gazebo>
  <gazebo reference="leg_r6_link">
    <mu1>1.5</mu1>
    <mu2>1.5</mu2>
    <self_collide>1</self_collide>
    <kp value="1000000.0"/>
    <kd value="100.0"/>
    <maxVel>1.0</maxVel>
    <minDepth>0.00</minDepth>
  </gazebo>
  <gazebo reference="leg_r_f1_link">
    <mu1>1.5</mu1>
    <mu2>1.5</mu2>
    <self_collide>1</self_collide>
    <kp value="1000000.0"/>
    <kd value="100.0"/>
    <maxVel>1.0</maxVel>
    <minDepth>0.00</minDepth>
  </gazebo>
  <gazebo reference="leg_r_f2_link">
    <mu1>1.5</mu1>
    <mu2>1.5</mu2>
    <self_collide>1</self_collide>
    <kp value="1000000.0"/>
    <kd value="100.0"/>
    <maxVel>1.0</maxVel>
    <minDepth>0.00</minDepth>
  </gazebo>
  <gazebo reference="leg_r_f3_link">
    <mu1>1.5</mu1>
    <mu2>1.5</mu2>
    <self_collide>1</self_collide>
    <kp value="1000000.0"/>
    <kd value="100.0"/>
    <maxVel>1.0</maxVel>
    <minDepth>0.00</minDepth>
  </gazebo>
  <gazebo reference="leg_r_f4_link">
    <mu1>1.5</mu1>
    <mu2>1.5</mu2>
    <self_collide>1</self_collide>
    <kp value="1000000.0"/>
    <kd value="100.0"/>
    <maxVel>1.0</maxVel>
    <minDepth>0.00</minDepth>
  </gazebo>
  <!-- ************* gazebo transmission *************** -->
  <transmission name="leg_r1_tran">
    <type>transmission_interface/SimpleTransmission</type>
    <joint name="leg_r1_joint">
      <hardwareInterface>hardware_interface/EffortJointInterface</hardwareInterface>
    </joint>
    <actuator name="leg_r1_motor">
      <hardwareInterface>hardware_interface/EffortJointInterface</hardwareInterface>
      <mechanicalReduction>1</mechanicalReduction>
      <maxVelocity>2.87</maxVelocity>
      <!-- 85rpm -->
      <maxEffort>182</maxEffort>
      <!-- 36Nm -->
    </actuator>
  </transmission>
  <transmission name="leg_r2_tran">
    <type>transmission_interface/SimpleTransmission</type>
    <joint name="leg_r2_joint">
      <hardwareInterface>hardware_interface/EffortJointInterface</hardwareInterface>
    </joint>
    <actuator name="leg_r2_motor">
      <hardwareInterface>hardware_interface/EffortJointInterface</hardwareInterface>
      <mechanicalReduction>1</mechanicalReduction>
      <maxVelocity>2.87</maxVelocity>
      <!-- 160rpm -->
      <maxEffort>182</maxEffort>
      <!-- 94Nm -->
    </actuator>
  </transmission>
  <transmission name="leg_r3_tran">
    <type>transmission_interface/SimpleTransmission</type>
    <joint name="leg_r3_joint">
      <hardwareInterface>hardware_interface/EffortJointInterface</hardwareInterface>
    </joint>
    <actuator name="leg_r3_motor">
      <hardwareInterface>hardware_interface/EffortJointInterface</hardwareInterface>
      <mechanicalReduction>1</mechanicalReduction>
      <maxVelocity>2.6545</maxVelocity>
      <!-- 160rpm -->
      <maxEffort>278</maxEffort>
      <!-- 94Nm -->
    </actuator>
  </transmission>
  <transmission name="leg_r4_tran">
    <type>transmission_interface/SimpleTransmission</type>
    <joint name="leg_r4_joint">
      <hardwareInterface>hardware_interface/EffortJointInterface</hardwareInterface>
    </joint>
    <actuator name="leg_r4_motor">
      <hardwareInterface>hardware_interface/EffortJointInterface</hardwareInterface>
      <mechanicalReduction>1</mechanicalReduction>
      <maxVelocity>2.6545</maxVelocity>
      <!-- 85rpm -->
      <maxEffort>278</maxEffort>
      <!-- 36Nm -->
    </actuator>
  </transmission>
  <transmission name="leg_r5_tran">
    <type>transmission_interface/SimpleTransmission</type>
    <joint name="leg_r5_joint">
      <hardwareInterface>hardware_interface/EffortJointInterface</hardwareInterface>
    </joint>
    <actuator name="leg_r5_motor">
      <hardwareInterface>hardware_interface/EffortJointInterface</hardwareInterface>
      <mechanicalReduction>1</mechanicalReduction>
    </actuator>
  </transmission>
  <transmission name="leg_r6_tran">
    <type>transmission_interface/SimpleTransmission</type>
    <joint name="leg_r6_joint">
      <hardwareInterface>hardware_interface/EffortJointInterface</hardwareInterface>
    </joint>
    <actuator name="leg_r6_motor">
      <hardwareInterface>hardware_interface/EffortJointInterface</hardwareInterface>
      <mechanicalReduction>1</mechanicalReduction>
    </actuator>
  </transmission>
  <!-- ************************************************************ -->
  <!-- ************************ Left zarm ************************** -->
  <!-- ************************************************************ -->
  <link name="zarm_l1_Link">
    <inertial>
      <origin rpy="0 0 0" xyz="0.00035297 0.0054003 0.054195"/>
      <mass value="0.9535"/>
      <inertia ixx="0.0012763" ixy="5.61E-06" ixz="1.12E-06" iyy="0.0012519" iyz="3.58E-05" izz="0.0010663"/>
    </inertial>
    <visual>
      <origin rpy="0 0 0" xyz="0 0 0"/>
      <geometry>
        <mesh filename="package://legged_hunter_description/meshes/zarm_l1_Link.STL"/>
      </geometry>
      <material name="">
        <color rgba="0.79216 0.81961 0.93333 1"/>
      </material>
    </visual>
  </link>
  <joint name="zarm_l1_joint" type="revolute">
    <origin rpy="0 -1.0472 -1.5708" xyz="0 0.12279 0.40213"/>
    <parent link="base_link"/>
    <child link="zarm_l1_Link"/>
    <axis xyz="0 0 1"/>
    <limit effort="90" lower="-3.14" upper="3.14" velocity="3.14"/>
  </joint>
  <link name="zarm_l2_Link">
    <inertial>
      <origin rpy="0 0 0" xyz="0.055439 -0.090985 -0.032863"/>
      <mass value="1.2"/>
      <inertia ixx="0.0025886" ixy="0.00049571" ixz="0.00023309" iyy="0.001704" iyz="-0.00049499" izz="0.002642"/>
    </inertial>
    <visual>
      <origin rpy="0 0 0" xyz="0 0 0"/>
      <geometry>
        <mesh filename="package://legged_hunter_description/meshes/zarm_l2_Link.STL"/>
      </geometry>
      <material name="">
        <color rgba="0.79216 0.81961 0.93333 1"/>
      </material>
    </visual>
  </link>
  <joint name="zarm_l2_joint" type="revolute">
    <origin rpy="1.5708 -1.0472 3.1416" xyz="0 0.039 0.063"/>
    <parent link="zarm_l1_Link"/>
    <child link="zarm_l2_Link"/>
    <axis xyz="0 0 1"/>
    <limit effort="90" lower="0" upper="2.093" velocity="3.14"/>
  </joint>
  <link name="zarm_l3_Link">
    <inertial>
      <origin rpy="0 0 0" xyz="0.0048486 -0.00016012 0.11131"/>
      <mass value="1.0637"/>
      <inertia ixx="0.0025964" ixy="5.74E-06" ixz="-9.7E-05" iyy="0.002625" iyz="-8.2E-07" izz="0.0011718"/>
    </inertial>
    <visual>
      <origin rpy="0 0 0" xyz="0 0 0"/>
      <geometry>
        <mesh filename="package://legged_hunter_description/meshes/zarm_l3_Link.STL"/>
      </geometry>
      <material name="">
        <color rgba="0.79216 0.81961 0.93333 1"/>
      </material>
    </visual>
  </link>
  <joint name="zarm_l3_joint" type="revolute">
    <origin rpy="1.5708 0 0" xyz="0.060456 -0.152 -0.039"/>
    <parent link="zarm_l2_Link"/>
    <child link="zarm_l3_Link"/>
    <axis xyz="0 0 1"/>
    <limit effort="90" lower="-3.14" upper="3.14" velocity="3.14"/>
  </joint>
  <link name="zarm_l4_Link">
    <inertial>
      <origin rpy="0 0 0" xyz="2.47E-05 -0.084392 -0.031049"/>
      <mass value="0.5554"/>
      <inertia ixx="0.0011728" ixy="-4.9E-07" ixz="3.1E-07" iyy="0.00038472" iyz="-0.0002729" izz="0.0010442"/>
    </inertial>
    <visual>
      <origin rpy="0 0 0" xyz="0 0 0"/>
      <geometry>
        <mesh filename="package://legged_hunter_description/meshes/zarm_l4_Link.STL"/>
      </geometry>
      <material name="">
        <color rgba="0.79216 0.81961 0.93333 1"/>
      </material>
    </visual>
  </link>
  <joint name="zarm_l4_joint" type="revolute">
    <origin rpy="-1.5708 1.5708 1.5708" xyz="-0.039 0 0.123"/>
    <parent link="zarm_l3_Link"/>
    <child link="zarm_l4_Link"/>
    <axis xyz="0 0 1"/>
    <limit effort="90" lower="-2" upper="2" velocity="3.14"/>
  </joint>
  <link name="zarm_l5_Link">
    <inertial>
      <origin rpy="0 0 0" xyz="0.0077864 -0.00025521 0.047106"/>
      <mass value="0.5729"/>
      <inertia ixx="0.00065916" ixy="9.54E-06" ixz="-6E-05" iyy="0.00092404" iyz="1.58E-06" izz="0.00063648"/>
    </inertial>
    <visual>
      <origin rpy="0 0 0" xyz="0 0 0"/>
      <geometry>
        <mesh filename="package://legged_hunter_description/meshes/zarm_l5_Link.STL"/>
      </geometry>
      <material name="">
        <color rgba="0.79216 0.81961 0.93333 1"/>
      </material>
    </visual>
  </link>
  <joint name="zarm_l5_joint" type="revolute">
    <origin rpy="1.5708 1.5708 0" xyz="0 -0.1461 -0.039"/>
    <parent link="zarm_l4_Link"/>
    <child link="zarm_l5_Link"/>
    <axis xyz="0 0 1"/>
    <limit effort="90" lower="-3.14" upper="3.14" velocity="3.14"/>
  </joint>
  <link name="zarm_l6_Link">
    <inertial>
      <origin rpy="0 0 0" xyz="0 0.0066539 0.031141"/>
      <mass value="0.4316"/>
      <inertia ixx="0.00039901" ixy="-4.2E-07" ixz="-2.4E-07" iyy="0.00022416" iyz="-1.03E-06" izz="0.00038958"/>
    </inertial>
    <visual>
      <origin rpy="0 0 0" xyz="0 0 0"/>
      <geometry>
        <mesh filename="package://legged_hunter_description/meshes/zarm_l6_Link.STL"/>
      </geometry>
      <material name="">
        <color rgba="0.79216 0.81961 0.93333 1"/>
      </material>
    </visual>
  </link>
  <joint name="zarm_l6_joint" type="revolute">
    <origin rpy="0 -1.5708 0" xyz="0.031 0 0.1289"/>
    <parent link="zarm_l5_Link"/>
    <child link="zarm_l6_Link"/>
    <axis xyz="0 0 1"/>
    <limit effort="90" lower="-1.047" upper="1.047" velocity="3.14"/>
  </joint>
  <link name="zarm_l7_Link">
    <inertial>
      <origin rpy="0 0 0" xyz="0 0.028046 0.034646"/>
      <mass value="0.23075"/>
      <inertia ixx="0.00039565" ixy="0" ixz="0" iyy="0.0003459" iyz="1.9E-05" izz="0.000148"/>
    </inertial>
    <visual>
      <origin rpy="0 0 0" xyz="0 0 0"/>
      <geometry>
        <mesh filename="package://legged_hunter_description/meshes/zarm_l7_Link.STL"/>
      </geometry>
      <material name="">
        <color rgba="0.79216 0.81961 0.93333 1"/>
      </material>
    </visual>
  </link>
  <joint name="zarm_l7_joint" type="revolute">
    <origin rpy="1.5708 -1.5708 0" xyz="0 -0.0374 0.031"/>
    <parent link="zarm_l6_Link"/>
    <child link="zarm_l7_Link"/>
    <axis xyz="0 0 1"/>
    <limit effort="90" lower="-1.57" upper="1.57" velocity="3.14"/>
  </joint>
  <joint name="zarm_l_fixed_1" type="fixed">
    <origin rpy="0 0 0" xyz="0.0 0.0 0.0"/>
    <parent link="zarm_l7_Link"/>
    <child link="zarm_l_f1_link"/>
  </joint>
  <link name="zarm_l_f1_link">
    <inertial>
      <mass value="0.01"/>
      <inertia ixx="0.000001" ixy="0" ixz="0" iyy="0.000001" iyz="0" izz="0.000001"/>
    </inertial>
    <visual>
      <origin rpy="0 0 0" xyz="0 0 0"/>
      <geometry>
        <sphere radius="0.001"/>
      </geometry>
    </visual>
    <collision>
      <origin rpy="0 0 0" xyz="0 0 0"/>
      <geometry>
        <sphere radius="0.001"/>
      </geometry>
    </collision>
  </link>
  <gazebo reference="zarm_l1_Link">
    <mu1>0.6</mu1>
    <mu2>0.6</mu2>
    <self_collide>1</self_collide>
  </gazebo>
  <gazebo reference="zarm_l2_Link">
    <mu1>0.6</mu1>
    <mu2>0.6</mu2>
    <self_collide>1</self_collide>
  </gazebo>
  <gazebo reference="zarm_l3_Link">
    <mu1>0.6</mu1>
    <mu2>0.6</mu2>
    <self_collide>1</self_collide>
  </gazebo>
  <gazebo reference="zarm_l4_Link">
    <mu1>0.6</mu1>
    <mu2>0.6</mu2>
    <self_collide>1</self_collide>
  </gazebo>
  <gazebo reference="zarm_l5_Link">
    <mu1>0.6</mu1>
    <mu2>0.6</mu2>
    <self_collide>1</self_collide>
  </gazebo>
  <gazebo reference="zarm_l6_Link">
    <mu1>0.6</mu1>
    <mu2>0.6</mu2>
    <self_collide>1</self_collide>
  </gazebo>
  <gazebo reference="zarm_l7_Link">
    <mu1>0.6</mu1>
    <mu2>0.6</mu2>
    <self_collide>1</self_collide>
  </gazebo>
  <gazebo reference="zarm_l_f1_link">
    <mu1>1.5</mu1>
    <mu2>1.5</mu2>
    <self_collide>1</self_collide>
    <kp value="1000000.0"/>
    <kd value="100.0"/>
    <maxVel>1.0</maxVel>
    <minDepth>0.00</minDepth>
  </gazebo>
  <transmission name="zarm_l1_tran">
    <type>transmission_interface/SimpleTransmission</type>
    <joint name="zarm_l1_joint">
      <hardwareInterface>hardware_interface/EffortJointInterface</hardwareInterface>
    </joint>
    <actuator name="zarm_l1_motor">
      <hardwareInterface>hardware_interface/EffortJointInterface</hardwareInterface>
      <mechanicalReduction>1</mechanicalReduction>
      <maxVelocity>2.87</maxVelocity>
      <maxEffort>182</maxEffort>
    </actuator>
  </transmission>
  <transmission name="zarm_l2_tran">
    <type>transmission_interface/SimpleTransmission</type>
    <joint name="zarm_l2_joint">
      <hardwareInterface>hardware_interface/EffortJointInterface</hardwareInterface>
    </joint>
    <actuator name="zarm_l2_motor">
      <hardwareInterface>hardware_interface/EffortJointInterface</hardwareInterface>
      <mechanicalReduction>1</mechanicalReduction>
      <maxVelocity>2.87</maxVelocity>
      <maxEffort>182</maxEffort>
    </actuator>
  </transmission>
  <transmission name="zarm_l3_tran">
    <type>transmission_interface/SimpleTransmission</type>
    <joint name="zarm_l3_joint">
      <hardwareInterface>hardware_interface/EffortJointInterface</hardwareInterface>
    </joint>
    <actuator name="zarm_l3_motor">
      <hardwareInterface>hardware_interface/EffortJointInterface</hardwareInterface>
      <mechanicalReduction>1</mechanicalReduction>
      <maxVelocity>2.6545</maxVelocity>
      <maxEffort>278</maxEffort>
    </actuator>
  </transmission>
  <transmission name="zarm_l4_tran">
    <type>transmission_interface/SimpleTransmission</type>
    <joint name="zarm_l4_joint">
      <hardwareInterface>hardware_interface/EffortJointInterface</hardwareInterface>
    </joint>
    <actuator name="zarm_l4_motor">
      <hardwareInterface>hardware_interface/EffortJointInterface</hardwareInterface>
      <mechanicalReduction>1</mechanicalReduction>
      <maxVelocity>2.6545</maxVelocity>
      <maxEffort>278</maxEffort>
    </actuator>
  </transmission>
  <transmission name="zarm_l5_tran">
    <type>transmission_interface/SimpleTransmission</type>
    <joint name="zarm_l5_joint">
      <hardwareInterface>hardware_interface/EffortJointInterface</hardwareInterface>
    </joint>
    <actuator name="zarm_l5_motor">
      <hardwareInterface>hardware_interface/EffortJointInterface</hardwareInterface>
      <mechanicalReduction>1</mechanicalReduction>
      <maxVelocity>2.6545</maxVelocity>
      <maxEffort>278</maxEffort>
    </actuator>
  </transmission>
  <transmission name="zarm_l6_tran">
    <type>transmission_interface/SimpleTransmission</type>
    <joint name="zarm_l6_joint">
      <hardwareInterface>hardware_interface/EffortJointInterface</hardwareInterface>
    </joint>
    <actuator name="zarm_l6_motor">
      <hardwareInterface>hardware_interface/EffortJointInterface</hardwareInterface>
      <mechanicalReduction>1</mechanicalReduction>
      <maxVelocity>2.6545</maxVelocity>
      <maxEffort>278</maxEffort>
    </actuator>
  </transmission>
  <transmission name="zarm_l7_tran">
    <type>transmission_interface/SimpleTransmission</type>
    <joint name="zarm_l7_joint">
      <hardwareInterface>hardware_interface/EffortJointInterface</hardwareInterface>
    </joint>
    <actuator name="zarm_l7_motor">
      <hardwareInterface>hardware_interface/EffortJointInterface</hardwareInterface>
      <mechanicalReduction>1</mechanicalReduction>
      <maxVelocity>2.6545</maxVelocity>
      <maxEffort>278</maxEffort>
    </actuator>
  </transmission>
  <!-- ************************************************************ -->
  <!-- ************************ Right zarm ************************** -->
  <!-- ************************************************************ -->
  <link name="zarm_r1_link">
    <inertial>
      <origin rpy="0 0 0" xyz="0.00035297 0.0054003 0.054195"/>
      <mass value="0.9535"/>
      <inertia ixx="0.0012763" ixy="5.61E-06" ixz="-1.12E-06" iyy="0.0012519" iyz="-3.58E-05" izz="0.0010663"/>
    </inertial>
    <visual>
      <origin rpy="0 0 0" xyz="0 0 0"/>
      <geometry>
        <mesh filename="package://legged_hunter_description/meshes/zarm_r1_link.STL"/>
      </geometry>
      <material name="">
        <color rgba="0.79216 0.81961 0.93333 1"/>
      </material>
    </visual>
  </link>
  <joint name="zarm_r1_joint" type="revolute">
    <origin rpy="0 -1.0472 1.5708" xyz="0 -0.12279 0.40213"/>
    <parent link="base_link"/>
    <child link="zarm_r1_link"/>
    <axis xyz="0 0 1"/>
    <limit effort="90" lower="-3.14" upper="3.14" velocity="3.14"/>
  </joint>
  <link name="zarm_r2_link">
    <inertial>
      <origin rpy="0 0 0" xyz="-0.055353 -0.091038 -0.032863"/>
      <mass value="1.2"/>
      <inertia ixx="0.0025867" ixy="-0.00050202" ixz="-0.00023665" iyy="0.0017031" iyz="-0.00052466" izz="0.0026449"/>
    </inertial>
    <visual>
      <origin rpy="0 0 0" xyz="0 0 0"/>
      <geometry>
        <mesh filename="package://legged_hunter_description/meshes/zarm_r2_link.STL"/>
      </geometry>
      <material name="">
        <color rgba="0.79216 0.81961 0.93333 1"/>
      </material>
    </visual>
  </link>
  <joint name="zarm_r2_joint" type="revolute">
    <origin rpy="1.5708 1.0472 0" xyz="0 -0.039 0.063"/>
    <parent link="zarm_r1_link"/>
    <child link="zarm_r2_link"/>
    <axis xyz="0 0 1"/>
    <limit effort="90" lower="-2.093" upper="0" velocity="3.14"/>
  </joint>
  <link name="zarm_r3_link">
    <inertial>
      <origin rpy="0 0 0" xyz="-0.0048486 0.00016012 0.11131"/>
      <mass value="1.0637"/>
      <inertia ixx="0.0025964" ixy="5.74E-06" ixz="9.7E-05" iyy="0.002625" iyz="8.2E-07" izz="0.0011718"/>
    </inertial>
    <visual>
      <origin rpy="0 0 0" xyz="0 0 0"/>
      <geometry>
        <mesh filename="package://legged_hunter_description/meshes/zarm_r3_link.STL"/>
      </geometry>
      <material name="">
        <color rgba="0.79216 0.81961 0.93333 1"/>
      </material>
    </visual>
  </link>
  <joint name="zarm_r3_joint" type="revolute">
    <origin rpy="1.5708 0 0" xyz="-0.060456 -0.152 -0.039"/>
    <parent link="zarm_r2_link"/>
    <child link="zarm_r3_link"/>
    <axis xyz="0 0 1"/>
    <limit effort="90" lower="-3.14" upper="3.14" velocity="3.14"/>
  </joint>
  <link name="zarm_r4_link">
    <inertial>
      <origin rpy="0 0 0" xyz="2.56E-05 -0.084392 -0.031048"/>
      <mass value="0.5554"/>
      <inertia ixx="0.0011725" ixy="-1.75E-06" ixz="5.1E-07" iyy="0.00038472" iyz="-0.00027023" izz="0.0010444"/>
    </inertial>
    <visual>
      <origin rpy="0 0 0" xyz="0 0 0"/>
      <geometry>
        <mesh filename="package://legged_hunter_description/meshes/zarm_r4_link.STL"/>
      </geometry>
      <material name="">
        <color rgba="0.79216 0.81961 0.93333 1"/>
      </material>
    </visual>
  </link>
  <joint name="zarm_r4_joint" type="revolute">
    <origin rpy="-1.5708 -1.5708 -1.5708" xyz="0.039 0 0.123"/>
    <parent link="zarm_r3_link"/>
    <child link="zarm_r4_link"/>
    <axis xyz="0 0 1"/>
    <limit effort="90" lower="-2" upper="2" velocity="3.14"/>
  </joint>
  <link name="zarm_r5_link">
    <inertial>
      <origin rpy="0 0 0" xyz="0.0077864 0.00025521 0.047106"/>
      <mass value="0.5729"/>
      <inertia ixx="0.00065916" ixy="9.54E-06" ixz="-6E-05" iyy="0.00092404" iyz="1.58E-06" izz="0.00063648"/>
    </inertial>
    <visual>
      <origin rpy="0 0 0" xyz="0 0 0"/>
      <geometry>
        <mesh filename="package://legged_hunter_description/meshes/zarm_r5_link.STL"/>
      </geometry>
      <material name="">
        <color rgba="0.79216 0.81961 0.93333 1"/>
      </material>
    </visual>
  </link>
  <joint name="zarm_r5_joint" type="revolute">
    <origin rpy="1.5708 -1.5708 0" xyz="0 -0.1461 -0.039"/>
    <parent link="zarm_r4_link"/>
    <child link="zarm_r5_link"/>
    <axis xyz="0 0 1"/>
    <limit effort="90" lower="-3.14" upper="3.14" velocity="3.14"/>
  </joint>
  <link name="zarm_r6_link">
    <inertial>
      <origin rpy="0 0 0" xyz="0 -0.006654 0.03114"/>
      <mass value="0.4316"/>
      <inertia ixx="0.00039901" ixy="-4.2E-07" ixz="2.4E-07" iyy="0.00022416" iyz="1.03E-06" izz="0.00038958"/>
    </inertial>
    <visual>
      <origin rpy="0 0 0" xyz="0 0 0"/>
      <geometry>
        <mesh filename="package://legged_hunter_description/meshes/zarm_r6_link.STL"/>
      </geometry>
      <material name="">
        <color rgba="0.79216 0.81961 0.93333 1"/>
      </material>
    </visual>
  </link>
  <joint name="zarm_r6_joint" type="revolute">
    <origin rpy="3.1416 -1.5708 0" xyz="-0.031 0 0.1289"/>
    <parent link="zarm_r5_link"/>
    <child link="zarm_r6_link"/>
    <axis xyz="0 0 1"/>
    <limit effort="90" lower="-1.047" upper="1.047" velocity="3.14"/>
  </joint>
  <link name="zarm_r7_link">
    <inertial>
      <origin rpy="0 0 0" xyz="-0.00078364 0.028035 0.034646"/>
      <mass value="0.23075"/>
      <inertia ixx="0.00039565" ixy="1.4E-06" ixz="-5.31E-07" iyy="0.0003459" iyz="1.9E-05" izz="0.000148"/>
    </inertial>
    <visual>
      <origin rpy="0 0 0" xyz="0 0 0"/>
      <geometry>
        <mesh filename="package://legged_hunter_description/meshes/zarm_r7_link.STL"/>
      </geometry>
      <material name="">
        <color rgba="0.79216 0.81961 0.93333 1"/>
      </material>
    </visual>
  </link>
  <joint name="zarm_r7_joint" type="revolute">
    <origin rpy="1.5708 -1.5708 0" xyz="0 -0.0374 0.031"/>
    <parent link="zarm_r6_link"/>
    <child link="zarm_r7_link"/>
    <axis xyz="0 0 1"/>
    <limit effort="90" lower="-1.57" upper="1.57" velocity="3.14"/>
  </joint>
  <joint name="zarm_r_fixed_1" type="fixed">
    <origin rpy="0 0 0" xyz="0.28 0.0 0.0"/>
    <parent link="zarm_r7_link"/>
    <child link="zarm_r_f1_link"/>
  </joint>
  <link name="zarm_r_f1_link">
    <inertial>
      <mass value="0.01"/>
      <inertia ixx="0.000001" ixy="0" ixz="0" iyy="0.000001" iyz="0" izz="0.000001"/>
    </inertial>
    <visual>
      <origin rpy="0 0 0" xyz="0 0 0"/>
      <geometry>
        <sphere radius="0.001"/>
      </geometry>
    </visual>
    <collision>
      <origin rpy="0 0 0" xyz="0 0 0"/>
      <geometry>
        <sphere radius="0.001"/>
      </geometry>
    </collision>
  </link>
  <gazebo reference="zarm_r1_link">
    <mu1>0.6</mu1>
    <mu2>0.6</mu2>
    <self_collide>1</self_collide>
  </gazebo>
  <gazebo reference="zarm_r2_link">
    <mu1>0.6</mu1>
    <mu2>0.6</mu2>
    <self_collide>1</self_collide>
  </gazebo>
  <gazebo reference="zarm_r3_link">
    <mu1>0.6</mu1>
    <mu2>0.6</mu2>
    <self_collide>1</self_collide>
  </gazebo>
  <gazebo reference="zarm_r4_link">
    <mu1>0.6</mu1>
    <mu2>0.6</mu2>
    <self_collide>1</self_collide>
  </gazebo>
  <gazebo reference="zarm_r5_link">
    <mu1>0.6</mu1>
    <mu2>0.6</mu2>
    <self_collide>1</self_collide>
  </gazebo>
  <gazebo reference="zarm_r6_link">
    <mu1>0.6</mu1>
    <mu2>0.6</mu2>
    <self_collide>1</self_collide>
  </gazebo>
  <gazebo reference="zarm_r7_link">
    <mu1>0.6</mu1>
    <mu2>0.6</mu2>
    <self_collide>1</self_collide>
  </gazebo>
  <gazebo reference="zarm_r_f1_link">
    <mu1>1.5</mu1>
    <mu2>1.5</mu2>
    <self_collide>1</self_collide>
    <kp value="1000000.0"/>
    <kd value="100.0"/>
    <maxVel>1.0</maxVel>
    <minDepth>0.00</minDepth>
  </gazebo>
  <transmission name="zarm_r1_tran">
    <type>transmission_interface/SimpleTransmission</type>
    <joint name="zarm_r1_joint">
      <hardwareInterface>hardware_interface/EffortJointInterface</hardwareInterface>
    </joint>
    <actuator name="zarm_r1_motor">
      <hardwareInterface>hardware_interface/EffortJointInterface</hardwareInterface>
      <mechanicalReduction>1</mechanicalReduction>
      <maxVelocity>2.87</maxVelocity>
      <maxEffort>182</maxEffort>
    </actuator>
  </transmission>
  <transmission name="zarm_r2_tran">
    <type>transmission_interface/SimpleTransmission</type>
    <joint name="zarm_r2_joint">
      <hardwareInterface>hardware_interface/EffortJointInterface</hardwareInterface>
    </joint>
    <actuator name="zarm_r2_motor">
      <hardwareInterface>hardware_interface/EffortJointInterface</hardwareInterface>
      <mechanicalReduction>1</mechanicalReduction>
      <maxVelocity>2.87</maxVelocity>
      <maxEffort>182</maxEffort>
    </actuator>
  </transmission>
  <transmission name="zarm_r3_tran">
    <type>transmission_interface/SimpleTransmission</type>
    <joint name="zarm_r3_joint">
      <hardwareInterface>hardware_interface/EffortJointInterface</hardwareInterface>
    </joint>
    <actuator name="zarm_r3_motor">
      <hardwareInterface>hardware_interface/EffortJointInterface</hardwareInterface>
      <mechanicalReduction>1</mechanicalReduction>
      <maxVelocity>2.6545</maxVelocity>
      <maxEffort>278</maxEffort>
    </actuator>
  </transmission>
  <transmission name="zarm_r4_tran">
    <type>transmission_interface/SimpleTransmission</type>
    <joint name="zarm_r4_joint">
      <hardwareInterface>hardware_interface/EffortJointInterface</hardwareInterface>
    </joint>
    <actuator name="zarm_r4_motor">
      <hardwareInterface>hardware_interface/EffortJointInterface</hardwareInterface>
      <mechanicalReduction>1</mechanicalReduction>
      <maxVelocity>2.6545</maxVelocity>
      <maxEffort>278</maxEffort>
    </actuator>
  </transmission>
  <transmission name="zarm_r5_tran">
    <type>transmission_interface/SimpleTransmission</type>
    <joint name="zarm_r5_joint">
      <hardwareInterface>hardware_interface/EffortJointInterface</hardwareInterface>
    </joint>
    <actuator name="zarm_r5_motor">
      <hardwareInterface>hardware_interface/EffortJointInterface</hardwareInterface>
      <mechanicalReduction>1</mechanicalReduction>
      <maxVelocity>2.6545</maxVelocity>
      <maxEffort>278</maxEffort>
    </actuator>
  </transmission>
  <transmission name="zarm_r6_tran">
    <type>transmission_interface/SimpleTransmission</type>
    <joint name="zarm_r6_joint">
      <hardwareInterface>hardware_interface/EffortJointInterface</hardwareInterface>
    </joint>
    <actuator name="zarm_r6_motor">
      <hardwareInterface>hardware_interface/EffortJointInterface</hardwareInterface>
      <mechanicalReduction>1</mechanicalReduction>
      <maxVelocity>2.6545</maxVelocity>
      <maxEffort>278</maxEffort>
    </actuator>
  </transmission>
  <transmission name="zarm_r7_tran">
    <type>transmission_interface/SimpleTransmission</type>
    <joint name="zarm_r7_joint">
      <hardwareInterface>hardware_interface/EffortJointInterface</hardwareInterface>
    </joint>
    <actuator name="zarm_r7_motor">
      <hardwareInterface>hardware_interface/EffortJointInterface</hardwareInterface>
      <mechanicalReduction>1</mechanicalReduction>
      <maxVelocity>2.6545</maxVelocity>
      <maxEffort>278</maxEffort>
    </actuator>
  </transmission>
  <!-- <xacro:include filename="$(find legged_perceptive_description)/urdf/sensor_t265.xacro"/> -->
  <!-- <xacro:include filename="$(find legged_perceptive_description)/urdf/mid360.xacro"/> -->
  <!-- <xacro:include filename="$(find legged_perceptive_description)/urdf/livox_mid360.xacro"/>
    <xacro:include filename="$(find legged_perceptive_description)/urdf/livox_mid361.xacro"/> -->
  <material name="front_camera_aluminum">
    <color rgba="0.5 0.5 0.5 1"/>
  </material>
  <!-- camera body, with origin at bottom screw mount -->
  <joint name="front_camera_joint" type="fixed">
    <origin rpy="3.141 1.2 0" xyz="0.25 -0.0 0.08"/>
    <parent link="base_link"/>
    <child link="front_camera_bottom_screw_frame"/>
  </joint>
  <link name="front_camera_bottom_screw_frame"/>
  <joint name="front_camera_link_joint" type="fixed">
    <origin rpy="0 0 0" xyz="0 0.0175 0.0125"/>
    <parent link="front_camera_bottom_screw_frame"/>
    <child link="front_camera_link"/>
  </joint>
  <link name="front_camera_link">
    <visual>
      <origin rpy="1.5707963267948966 0 1.5707963267948966" xyz="0.0149 -0.0175 0"/>
      <geometry>
        <!-- <box size="${d435_cam_width} ${d435_cam_height} ${d435_cam_depth}"/> -->
        <mesh filename="package://realsense2_description/meshes/d435.dae"/>
        <!--<mesh filename="package://realsense2_description/meshes/d435/d435.dae" />-->
      </geometry>
      <material name="front_camera_aluminum"/>
    </visual>
    <collision>
      <origin rpy="0 0 0" xyz="0 -0.0175 0"/>
      <geometry>
        <box size="0.02505 0.09 0.025"/>
      </geometry>
    </collision>
    <inertial>
      <!-- The following are not reliable values, and should not be used for modeling -->
      <mass value="0.072"/>
      <origin xyz="0 0 0"/>
      <inertia ixx="0.003881243" ixy="0.0" ixz="0.0" iyy="0.000498940" iyz="0.0" izz="0.003879257"/>
    </inertial>
  </link>
  <!-- camera depth joints and links -->
  <joint name="front_camera_depth_joint" type="fixed">
    <origin rpy="0 0 0" xyz="0 0 0"/>
    <parent link="front_camera_link"/>
    <child link="front_camera_depth_frame"/>
  </joint>
  <link name="front_camera_depth_frame"/>
  <joint name="front_camera_depth_optical_joint" type="fixed">
    <origin rpy="-1.5707963267948966 0 -1.5707963267948966" xyz="0 0 0"/>
    <parent link="front_camera_depth_frame"/>
    <child link="front_camera_depth_optical_frame"/>
  </joint>
  <link name="front_camera_depth_optical_frame"/>
  <!-- camera left IR joints and links -->
  <joint name="front_camera_left_ir_joint" type="fixed">
    <origin rpy="0 0 0" xyz="0 0.0 0"/>
    <parent link="front_camera_depth_frame"/>
    <child link="front_camera_left_ir_frame"/>
  </joint>
  <link name="front_camera_left_ir_frame"/>
  <joint name="front_camera_left_ir_optical_joint" type="fixed">
    <origin rpy="-1.5707963267948966 0 -1.5707963267948966" xyz="0 0 0"/>
    <parent link="front_camera_left_ir_frame"/>
    <child link="front_camera_left_ir_optical_frame"/>
  </joint>
  <link name="front_camera_left_ir_optical_frame"/>
  <!-- camera right IR joints and links -->
  <joint name="front_camera_right_ir_joint" type="fixed">
    <origin rpy="0 0 0" xyz="0 -0.05 0"/>
    <parent link="front_camera_depth_frame"/>
    <child link="front_camera_right_ir_frame"/>
  </joint>
  <link name="front_camera_right_ir_frame"/>
  <joint name="front_camera_right_ir_optical_joint" type="fixed">
    <origin rpy="-1.5707963267948966 0 -1.5707963267948966" xyz="0 0 0"/>
    <parent link="front_camera_right_ir_frame"/>
    <child link="front_camera_right_ir_optical_frame"/>
  </joint>
  <link name="front_camera_right_ir_optical_frame"/>
  <!-- camera color joints and links -->
  <joint name="front_camera_color_joint" type="fixed">
    <origin rpy="0 0 0" xyz="0 0.015 0"/>
    <parent link="front_camera_depth_frame"/>
    <child link="front_camera_color_frame"/>
  </joint>
  <link name="front_camera_color_frame"/>
  <joint name="front_camera_color_optical_joint" type="fixed">
    <origin rpy="-1.5707963267948966 0 -1.5707963267948966" xyz="0 0 0"/>
    <parent link="front_camera_color_frame"/>
    <child link="front_camera_color_optical_frame"/>
  </joint>
  <link name="front_camera_color_optical_frame"/>
  <gazebo reference="front_camera_link">
    <self_collide>0</self_collide>
    <enable_wind>0</enable_wind>
    <kinematic>0</kinematic>
    <gravity>1</gravity>
    <!--<mu>1</mu>-->
    <mu2>1</mu2>
    <fdir1>0 0 0</fdir1>
    <!--<slip1>0</slip1>
            <slip2>0</slip2>-->
    <kp>1e+13</kp>
    <kd>1</kd>
    <!--<max_vel>0.01</max_vel>
            <min_depth>0</min_depth>-->
    <sensor name="front_cameracolor" type="camera">
      <camera name="front_camera">
        <horizontal_fov>1.2112585008840648</horizontal_fov>
        <image>
          <width>640</width>
          <height>480</height>
          <format>RGB_INT8</format>
        </image>
        <clip>
          <near>0.1</near>
          <far>100</far>
        </clip>
        <noise>
          <type>gaussian</type>
          <mean>0.0</mean>
          <stddev>0.007</stddev>
        </noise>
      </camera>
      <always_on>1</always_on>
      <update_rate>30</update_rate>
      <visualize>1</visualize>
    </sensor>
    <sensor name="front_cameraired1" type="camera">
      <camera name="front_camera">
        <horizontal_fov>1.4870205226991688</horizontal_fov>
        <image>
          <width>1280</width>
          <height>720</height>
          <format>L_INT8</format>
        </image>
        <clip>
          <near>0.1</near>
          <far>100</far>
        </clip>
        <noise>
          <type>gaussian</type>
          <mean>0.0</mean>
          <stddev>0.05</stddev>
        </noise>
      </camera>
      <always_on>1</always_on>
      <update_rate>90</update_rate>
      <visualize>0</visualize>
    </sensor>
    <sensor name="front_cameraired2" type="camera">
      <camera name="front_camera">
        <horizontal_fov>1.4870205226991688</horizontal_fov>
        <image>
          <width>1280</width>
          <height>720</height>
          <format>L_INT8</format>
        </image>
        <clip>
          <near>0.1</near>
          <far>100</far>
        </clip>
        <noise>
          <type>gaussian</type>
          <mean>0.0</mean>
          <stddev>0.05</stddev>
        </noise>
      </camera>
      <always_on>1</always_on>
      <update_rate>90</update_rate>
      <visualize>0</visualize>
    </sensor>
    <sensor name="front_cameradepth" type="depth">
      <camera name="front_camera">
        <horizontal_fov>1.4870205226991688</horizontal_fov>
        <image>
          <width>1280</width>
          <height>720</height>
        </image>
        <clip>
          <near>0.1</near>
          <far>5</far>
        </clip>
        <noise>
          <type>gaussian</type>
          <mean>0.0</mean>
          <stddev>0.100</stddev>
        </noise>
      </camera>
      <always_on>1</always_on>
      <update_rate>10</update_rate>
      <visualize>0</visualize>
    </sensor>
  </gazebo>
  <gazebo>
    <plugin filename="librealsense_gazebo_plugin.so" name="front_camera">
      <prefix>front_camera</prefix>
      <depthTopicName>aligned_depth_to_color/image_raw</depthTopicName>
      <depthCameraInfoTopicName>depth/camera_info</depthCameraInfoTopicName>
      <colorTopicName>color/image_raw</colorTopicName>
      <colorCameraInfoTopicName>color/camera_info</colorCameraInfoTopicName>
      <colorOpticalframeName>front_camera_color_optical_frame</colorOpticalframeName>
      <depthOpticalframeName>front_camera_depth_optical_frame</depthOpticalframeName>
      <rangeMinDepth>0.2</rangeMinDepth>
      <rangeMaxDepth>5.0</rangeMaxDepth>
      <pointCloud>True</pointCloud>
      <pointCloudTopicName>depth/color/points</pointCloudTopicName>
      <pointCloudCutoff>0.2</pointCloudCutoff>
      <pointCloudCutoffMax>5.0</pointCloudCutoffMax>
    </plugin>
  </gazebo>
  <!-- <xacro:sensor_t265 name="tracking_camera" topics_ns="tracking_camera" parent="base">
        <origin xyz="0.16 0 0.085" rpy="0 -1.04 0"/>
    </xacro:sensor_t265> -->
  <!-- <xacro:livox_mid360 name="livox_right" parent="base_link">
        <origin xyz="0.365 -0.068 -0.030" rpy="-2.59 1.03 3.09"/>
    </xacro:livox_mid360>

    <xacro:livox_mid361 name="livox_left" parent="base_link">
        <origin xyz="0.365 0.068 -0.030" rpy="2.59 1.03 -3.09"/>
    </xacro:livox_mid361> -->
</robot>

